  Retrying (Retry(total=4, connect=None, read=None, redirect=None, status=None)) after connection broken by 'NewConnectionError('<pip._vendor.urllib3.connection.VerifiedHTTPSConnection object at 0x7fc9ee26b7b8>: Failed to establish a new connection: [Errno -3] Temporary failure in name resolution',)': /simple/pypandoc/
  Retrying (Retry(total=3, connect=None, read=None, redirect=None, status=None)) after connection broken by 'NewConnectionError('<pip._vendor.urllib3.connection.VerifiedHTTPSConnection object at 0x7fc9ee26b710>: Failed to establish a new connection: [Errno -3] Temporary failure in name resolution',)': /simple/pypandoc/
  Retrying (Retry(total=2, connect=None, read=None, redirect=None, status=None)) after connection broken by 'NewConnectionError('<pip._vendor.urllib3.connection.VerifiedHTTPSConnection object at 0x7fc9ee26ba90>: Failed to establish a new connection: [Errno -3] Temporary failure in name resolution',)': /simple/pypandoc/
  Retrying (Retry(total=1, connect=None, read=None, redirect=None, status=None)) after connection broken by 'NewConnectionError('<pip._vendor.urllib3.connection.VerifiedHTTPSConnection object at 0x7fc9ee26b668>: Failed to establish a new connection: [Errno -3] Temporary failure in name resolution',)': /simple/pypandoc/
  Retrying (Retry(total=0, connect=None, read=None, redirect=None, status=None)) after connection broken by 'NewConnectionError('<pip._vendor.urllib3.connection.VerifiedHTTPSConnection object at 0x7fc9ee26b320>: Failed to establish a new connection: [Errno -3] Temporary failure in name resolution',)': /simple/pypandoc/
  Could not find a version that satisfies the requirement pypandoc~=1.3.0 (from versions: )
No matching distribution found for pypandoc~=1.3.0
